Workbook

Sheet Sheet1
A1: Adresse | B1: Salgspris | C1: Salgsdato | D1: Værelser | E1: Kvm | F1: Prisjustering | G1: Pris_kvm | H1: URL | I1: Rækkefølge | J1: id | K1: vejnavn | L1: husnr | M1: etage | N1: dør | O1: postnr | P1: postnrnavn | Q1: matrikelnr | R1: esrejendomsnr | S1: etrs89koordinat_øst | T1: etrs89koordinat_nord | U1: wgs84koordinat_bredde | V1: wgs84koordinat_længde | W1: ddkn_km1 | X1: sognenavn | Y1: opstillingskredsnavn | Z1: zone | AA1: højde | AB1: afstemningsområdenavn | AC1: Fiber | AD1: Støj | AE1: Radon | AF1: Hårdhed af vand | AG1: Afstand risikovirksomhed | AH1: Afstand vindmølle | AI1: Asbest | AJ1: PCB | AK1: Tungmetaller | AL1: Anvendelse | AM1: Boligtype | AN1: Opførselsesår | AO1: Ombygningsår | AP1: Fredning | AQ1: Ejerforhold | AR1: Køkkenforhold | AS1: Antal Etager | AT1: Antal toiletter | AU1: Antal badeværelser | AV1: Antal værelser | AW1: Ydervægsmateriale | AX1: Tagmateriale | AY1: Varmeinstallation | AZ1: Opvarmningsmiddel | BA1: Supplerende varme | BB1: Bygning samlet areal | BC1: Borgerservice | BD1: Hovedbanegård | BE1: Centrum | BF1: Kyst | BG1: Energimærke | BH1: Area
A2: Ceresbyen 66, 3. 2, 8000 Aarhus C | B2: 3950000 | C2: 44242 | D2: 3 | E2: 96 | G2: 41145.833 | H2: https://www.dingeo.dk/adresse/8000-Aarhus-C/Ceresbyen-66/3-2 | I2: 1 | J2: 7eb4b108-7486-48d5-83cb-7e2c4ed71458 | K2: Ceresbyen | L2: 66 | M2: 3 | N2: 2 | O2: 8000 | P2: Aarhus C | Q2: 1276a | R2: 407742 | S2: 574188.11 | T2: 6224161 | U2: 56.156688 | V2: 10.194395 | W2: 1km_6224_574 | X2: Vor Frue | Y2: Aarhus Nord | Z2: Byzone | AA2: 4.5 | AB2: VIA University College | AC2: 1 | AD2: 3 | AE2: Meget lav | AF2: 12 - 18 | AG2: Afstand: 1,74 km | AH2: Afstand: 11,00 km | AI2: ✓Asbest | AJ2: ✓PCB | AK2: !Tungmetaller | AL2: Bolig i etageejendom, flerfamiliehus eller to-familiehus | AM2: Egentlig beboelseslejlighed (boligenhed med eget køkken) | AN2: 2017 | AO2: - | AP2: - | AQ2: Aktie-, anpart- eller andet selskab (undtagen interessent­skab) | AR2: Eget køkken med afløb | AS2: 9 | AT2: 1 | AU2: 1 | AV2: 3 | AW2: Betonelementer | AX2: Tagpap med lille hældning | AY2: Fjernvarme/blokvarme | AZ2: - | BA2: (UDFASES) Bygningen har ingen supplerende varme | BB2: 5335 m2 | BC2: 1221.5548 | BD2: 953.59872 | BE2: 755.46827 | BF2: 1183.6876 | BG2: A2020 | BH2: Ceresbyen
A3: Tage-Hansens Gade 7, 5. tv, 8000 Aarhus C | B3: 2110000 | C3: 44237 | D3: 2 | E3: 69 | F3: -4 | G3: 30579.71 | H3: https://www.dingeo.dk/adresse/8000-Aarhus-C/Tage--Hansens-Gade-7/5-tv | I3: 2 | J3: 0a3f50c4-70d3-32b8-e044-0003ba298018 | K3: Tage-Hansens Gade | L3: 7 | M3: 5 | N3: tv | O3: 8000 | P3: Aarhus C | Q3: 12fa | R3: 488521 | S3: 573552.19 | T3: 6224251 | U3: 56.157595 | V3: 10.184184 | W3: 1km_6224_573 | X3: Møllevang | Y3: Aarhus Nord | Z3: Byzone | AA3: 19.5 | AB3: VIA University College | AC3: 0 | AD3: 1 | AE3: Meget lav | AF3: 12 - 18 | AG3: Afstand: 2,30 km | AH3: Afstand: 11,00 km | AI3: !Asbest | AJ3: !PCB | AK3: !Tungmetaller | AL3: Bolig i etageejendom, flerfamiliehus eller to-familiehus | AM3: Egentlig beboelseslejlighed (boligenhed med eget køkken) | AN3: 1945 | AO3: - | AP3: - | AQ3: Privatpersoner eller interessentskab | AR3: Eget køkken med afløb | AS3: 6 | AT3: 1 | AU3: 1 | AV3: 2 | AW3: Mursten | AX3: Tegl | AY3: Fjernvarme/blokvarme | AZ3: - | BA3: (UDFASES) Bygningen har ingen supplerende varme | BB3: 1203 m2 | BC3: 1857.3143 | BD3: 1506.5493 | BE3: 1391.153 | BF3: 1823.2921 | BG3: C | BH3: Vesterbro
A4: Irma Pedersens Gade 15, 4. 3, 8000 Aarhus C | B4: 1808158 | C4: 44228 | D4: 3 | E4: 100 | F4: -55 | G4: 18081.58 | H4: https://www.dingeo.dk/adresse/8000-Aarhus-C/Irma-Pedersens-Gade-15/4-3 | I4: 3 | J4: 90fd219a-b6e7-4a7c-8c7b-33314a75686b | K4: Irma Pedersens Gade | L4: 15 | M4: 4 | N4: 3 | O4: 8000 | P4: Aarhus C | Q4: 2148ep | R4: 992149 | S4: 576266.63 | T4: 6224961.9 | U4: 56.163554 | V4: 10.228079 | W4: 1km_6224_576 | X4: Aarhus Domsogn | Y4: Aarhus Øst | Z4: Byzone | AA4: 1.9 | AB4: DOKK1 | AC4: 1 | AD4: 1 | AE4: Meget lav | AF4: 12 - 18 | AG4: Afstand: 936 meter | AH4: Afstand: 12,00 km | AI4: ✓Asbest | AJ4: ✓PCB | AK4: !Tungmetaller | AL4: Bolig i etageejendom, flerfamiliehus eller to-familiehus | AM4: Egentlig beboelseslejlighed (boligenhed med eget køkken) | AN4: 2019 | AO4: - | AP4: - | AQ4: Privatpersoner eller interessentskab | AR4: Eget køkken med afløb | AS4: 17 | AT4: 1 | AU4: 1 | AV4: 3 | AW4: Betonelementer | AX4: Tagpap med lille hældning | AY4: Fjernvarme/blokvarme | AZ4: - | BA4: - | BB4: 32178 m2 | BC4: 1473.1527 | BD4: 2069.0639 | BE4: 1530.0307 | BF4: 337.96614 | BG4: A2015 | BH4: Århus Ø
A5: Ceres Allé 7, 12. 6, 8000 Aarhus C | B5: 1957500 | C5: 44227 | D5: 3 | E5: 97 | G5: 20180.412 | H5: https://www.dingeo.dk/adresse/8000-Aarhus-C/Ceres-Allé-7/12-6 | I5: 4 | J5: a9d920e8-dd17-44b9-846b-30803d590c0e | K5: Ceres Allé | L5: 7 | M5: 12 | N5: 6 | O5: 8000 | P5: Aarhus C | Q5: 4z | R5: 72961 | S5: 573994.8 | T5: 6223924.3 | U5: 56.154591 | V5: 10.191218 | W5: 1km_6223_573 | X5: Vor Frue | Y5: Aarhus Nord | Z5: Byzone | AA5: 4.2 | AB5: VIA University College | AC5: 1 | AD5: 1 | AE5: Meget lav | AF5: 12 - 18 | AG5: Afstand: 1,74 km | AH5: Afstand: 11,00 km | AI5: ✓Asbest | AJ5: ✓PCB | AK5: !Tungmetaller | AL5: Bolig i etageejendom, flerfamiliehus eller to-familiehus | AM5: Egentlig beboelseslejlighed (boligenhed med eget køkken) | AN5: 2016 | AO5: - | AP5: - | AQ5: Privatpersoner eller interessentskab | AR5: Eget køkken med afløb | AS5: 19 | AT5: 1 | AU5: 1 | AV5: 3 | AW5: Betonelementer | AX5: Tagpap med lille hældning | AY5: Fjernvarme/blokvarme | AZ5: - | BA5: (UDFASES) Bygningen har ingen supplerende varme | BB5: 17885 m2 | BC5: 1365.8123 | BD5: 960.27174 | BE5: 983.69389 | BF5: 1379.1071 | BG5: A2015 | BH5: Ceresbyen
A6: Schleppegrellsgade 28, 1. th, 8000 Aarhus C | B6: 1820000 | C6: 44227 | D6: 2 | E6: 44 | F6: -4 | G6: 41363.636 | H6: https://www.dingeo.dk/adresse/8000-Aarhus-C/Schleppegrellsgade-28/1-th | I6: 5 | J6: 0a3f50c4-0f6c-32b8-e044-0003ba298018 | K6: Schleppegrellsgade | L6: 28 | M6: 1 | N6: th | O6: 8000 | P6: Aarhus C | Q6: 801i | R6: 405065 | S6: 574063.69 | T6: 6223184 | U6: 56.147931 | V6: 10.192121 | W6: 1km_6223_574 | X6: Sankt Lukas | Y6: Aarhus Syd | Z6: Byzone | AA6: 11.4 | AB6: Lokalcenter Fr.Bjerg/Langenæs | AC6: 1 | AD6: 2 | AE6: Meget lav | AF6: 12 - 18 | AG6: Afstand: 1,38 km | AH6: Afstand: 11,00 km | AI6: ✓Asbest | AJ6: !PCB | AK6: !Tungmetaller | AL6: Bolig i etageejendom, flerfamiliehus eller to-familiehus | AM6: Egentlig beboelseslejlighed (boligenhed med eget køkken) | AN6: 1900 | AO6: - | AP6: - | AQ6: Aktie-, anpart- eller andet selskab (undtagen interessent­skab) | AR6: Eget køkken med afløb | AS6: 5 | AT6: 1 | AU6: 0 | AV6: 2 | AW6: Mursten | AX6: Tegl | AY6: Fjernvarme/blokvarme | AZ6: - | BA6: (UDFASES) Bygningen har ingen supplerende varme | BB6: 546 m2 | BC6: 1431.364 | BD6: 821.59269 | BE6: 1333.9141 | BF6: 1336.0196 | BG6: E | BH6: Frederiksbjerg
A7: Skovvejen 75, st, 8000 Aarhus C | B7: 2250000 | C7: 44222 | D7: 2 | E7: 47 | F7: 5 | G7: 47872.34 | H7: https://www.dingeo.dk/adresse/8000-Aarhus-C/Skovvejen-75/st | I7: 6 | J7: 0a3f50c4-362b-32b8-e044-0003ba298018 | K7: Skovvejen | L7: 75 | M7: st | O7: 8000 | P7: Aarhus C | Q7: 1427 | R7: 435908 | S7: 575632.75 | T7: 6225287 | U7: 56.166575 | V7: 10.217967 | W7: 1km_6225_575 | X7: Sankt Johannes | Y7: Aarhus Øst | Z7: Byzone | AA7: 10.4 | AB7: DOKK1 | AC7: 0 | AD7: 5 | AE7: Meget lav | AF7: 12 - 18 | AG7: Afstand: 1,37 km | AH7: Afstand: 12,00 km | AI7: !Asbest | AJ7: ✓PCB | AK7: !Tungmetaller | AL7: Bolig i etageejendom, flerfamiliehus eller to-familiehus | AM7: Egentlig beboelseslejlighed (boligenhed med eget køkken) | AN7: 1900 | AO7: 1981 | AP7: - | AQ7: Privatpersoner eller interessentskab | AR7: Eget køkken med afløb | AS7: 3 | AT7: 1 | AU7: 1 | AV7: 2 | AW7: Mursten | AX7: Fibercement herunder asbest | AY7: Fjernvarme/blokvarme | AZ7: - | BA7: (UDFASES) Bygningen har ingen supplerende varme | BB7: 162 m2 | BC7: 1511.0946 | BD7: 1989.6368 | BE7: 1296.7259 | BF7: 151.60514 | BG7: C | BH7: Trøjborg
A8: Studsgade 28, 1. th, 8000 Aarhus C | B8: 2850000 | C8: 44221 | D8: 3 | E8: 77 | F8: -6 | G8: 37012.987 | H8: https://www.dingeo.dk/adresse/8000-Aarhus-C/Studsgade-28/1-th | I8: 7 | J8: 0a3f50c4-6177-32b8-e044-0003ba298018 | K8: Studsgade | L8: 28 | M8: 1 | N8: th | O8: 8000 | P8: Aarhus C | Q8: 1053 | R8: 473648 | S8: 575221.56 | T8: 6224535.5 | U8: 56.15989 | V8: 10.211135 | W8: 1km_6224_575 | X8: Aarhus Domsogn | Y8: Aarhus Øst | Z8: Byzone | AA8: 3.7 | AB8: DOKK1 | AC8: 0 | AD8: 3 | AE8: Meget lav | AF8: 12 - 18 | AG8: Afstand: 1,06 km | AH8: Afstand: 12,00 km | AI8: ✓Asbest | AJ8: !PCB | AK8: !Tungmetaller | AL8: Bolig i etageejendom, flerfamiliehus eller to-familiehus | AM8: Egentlig beboelseslejlighed (boligenhed med eget køkken) | AN8: 1894 | AO8: 1979 | AP8: - | AQ8: Aktie-, anpart- eller andet selskab (undtagen interessent­skab) | AR8: Eget køkken med afløb | AS8: 2 | AT8: 1 | AU8: 1 | AV8: 3 | AW8: Mursten | AX8: Tegl | AY8: Fjernvarme/blokvarme | AZ8: - | BA8: (UDFASES) Bygningen har ingen supplerende varme | BB8: 271 m2 | BC8: 746.88283 | BD8: 1139.4011 | BE8: 444.70645 | BF8: 216.57691 | BG8: D | BH8: Latinerkvarteret
A9: Regenburgsgade 6, 3. tv, 8000 Aarhus C | B9: 1987500 | C9: 44221 | D9: 2 | E9: 66 | F9: -7 | G9: 30113.636 | H9: https://www.dingeo.dk/adresse/8000-Aarhus-C/Regenburgsgade-6/3-tv | I9: 8 | J9: 0a3f50c3-e807-32b8-e044-0003ba298018 | K9: Regenburgsgade | L9: 6 | M9: 3 | N9: tv | O9: 8000 | P9: Aarhus C | Q9: 12ev | R9: 375778 | S9: 573537 | T9: 6224207.5 | U9: 56.157206 | V9: 10.183928 | W9: 1km_6224_573 | X9: Møllevang | Y9: Aarhus Nord | Z9: Byzone | AA9: 17.6 | AB9: VIA University College | AC9: 0 | AD9: 1 | AE9: Meget lav | AF9: 12 - 18 | AG9: Afstand: 2,28 km | AH9: Afstand: 11,00 km | AI9: !Asbest | AJ9: !PCB | AK9: !Tungmetaller | AL9: Bolig i etageejendom, flerfamiliehus eller to-familiehus | AM9: Egentlig beboelseslejlighed (boligenhed med eget køkken) | AN9: 1945 | AO9: - | AP9: - | AQ9: Privatpersoner eller interessentskab | AR9: Eget køkken med afløb | AS9: 6 | AT9: 1 | AU9: 1 | AV9: 2 | AW9: Mursten | AX9: Tegl | AY9: Fjernvarme/blokvarme | AZ9: - | BA9: (UDFASES) Bygningen har ingen supplerende varme | BB9: 716 m2 | BC9: 1862.047 | BD9: 1497.3617 | BE9: 1404.9896 | BF9: 1836.1869 | BG9: C | BH9: Vesterbro
A10: Sjællandsgade 5, 1, 8000 Aarhus C | B10: 2900000 | C10: 44220 | D10: 4 | E10: 87 | F10: -3 | G10: 33333.333 | H10: https://www.dingeo.dk/adresse/8000-Aarhus-C/Sjællandsgade-5/1 | I10: 9 | J10: 0a3f50c4-188d-32b8-e044-0003ba298018 | K10: Sjællandsgade | L10: 5 | M10: 1 | O10: 8000 | P10: Aarhus C | Q10: 1000a | R10: 415559 | S10: 575103.56 | T10: 6224676.5 | U10: 56.161175 | V10: 10.209275 | W10: 1km_6224_575 | X10: Aarhus Domsogn | Y10: Aarhus Øst | Z10: Byzone | AA10: 5.7 | AB10: Samsøgades Skole | AC10: 1 | AD10: 1 | AE10: Meget lav | AF10: 12 - 18 | AG10: Afstand: 1,24 km | AH10: Afstand: 12,00 km | AI10: ✓Asbest | AJ10: !PCB | AK10: !Tungmetaller | AL10: Bolig i etageejendom, flerfamiliehus eller to-familiehus | AM10: Egentlig beboelseslejlighed (boligenhed med eget køkken) | AN10: 1877 | AO10: 2013 | AP10: - | AQ10: Privatpersoner eller interessentskab | AR10: Eget køkken med afløb | AS10: 2 | AT10: 1 | AU10: 1 | AV10: 4 | AW10: Mursten | AX10: Tegl | AY10: Fjernvarme/blokvarme | AZ10: - | BA10: (UDFASES) Bygningen har ingen supplerende varme | BB10: 304 m2 | BC10: 911.44945 | BD10: 1242.818 | BE10: 514.4751 | BF10: 369.0851 | BG10: D | BH10: Øgadekvarteret
A11: Sønderborggade 13, 2. mf, 8000 Aarhus C | B11: 1050000 | C11: 44217 | D11: 1 | E11: 35 | G11: 30000 | H11: https://www.dingeo.dk/adresse/8000-Aarhus-C/Sønderborggade-13/2-mf | I11: 10 | J11: 0a3f50c4-67d1-32b8-e044-0003ba298018 | K11: Sønderborggade | L11: 13 | M11: 2 | N11: mf | O11: 8000 | P11: Aarhus C | Q11: 727az | R11: 481217 | S11: 573402.07 | T11: 6222407 | U11: 56.141053 | V11: 10.18126 | W11: 1km_6222_573 | X11: Langenæs | Y11: Aarhus Syd | Z11: Byzone | AA11: 16.4 | AB11: Lokalcenter Fr.Bjerg/Langenæs | AC11: 0 | AD11: 1 | AE11: Meget lav | AF11: 12 - 18 | AG11: Afstand: 2,10 km | AH11: Afstand: 10,00 km | AI11: ✓Asbest | AJ11: !PCB | AK11: !Tungmetaller | AL11: Bolig i etageejendom, flerfamiliehus eller to-familiehus | AM11: Egentlig beboelseslejlighed (boligenhed med eget køkken) | AN11: 1960 | AO11: - | AP11: - | AQ11: Privatpersoner eller interessentskab | AR11: Eget køkken med afløb | AS11: 3 | AT11: 1 | AU11: 1 | AV11: 1 | AW11: Mursten | AX11: Tegl | AY11: Fjernvarme/blokvarme | AZ11: - | BA11: (UDFASES) Bygningen har ingen supplerende varme | BB11: 2391 m2 | BC11: 2398.5943 | BD11: 1779.9382 | BE11: 2353.5519 | BF11: 1843.4031 | BG11: D | BH11: Langenæs
A12: Paradisgade 5, st. th, 8000 Aarhus C | B12: 1390000 | C12: 44217 | D12: 2 | E12: 44 | F12: -7 | G12: 31590.909 | H12: https://www.dingeo.dk/adresse/8000-Aarhus-C/Paradisgade-5/st-th | I12: 11 | J12: 0a3f50c3-db6b-32b8-e044-0003ba298018 | K12: Paradisgade | L12: 5 | M12: st | N12: th | O12: 8000 | P12: Aarhus C | Q12: 1070g | R12: 360673 | S12: 575132.81 | T12: 6224550.5 | U12: 56.160038 | V12: 10.20971 | W12: 1km_6224_575 | X12: Aarhus Domsogn | Y12: Aarhus Øst | Z12: Byzone | AA12: 3.3 | AB12: DOKK1 | AC12: 0 | AD12: 4 | AE12: Meget lav | AF12: 12 - 18 | AG12: Afstand: 1,14 km | AH12: Afstand: 12,00 km | AI12: ✓Asbest | AJ12: !PCB | AK12: ✓Tungmetaller | AL12: Bolig i etageejendom, flerfamiliehus eller to-familiehus | AM12: Egentlig beboelseslejlighed (boligenhed med eget køkken) | AN12: 1866 | AO12: 1988 | AP12: - | AQ12: Privatpersoner eller interessentskab | AR12: Eget køkken med afløb | AS12: 3 | AT12: 1 | AU12: 1 | AV12: 2 | AW12: Mursten | AX12: Tagpap med stor hældning | AY12: Fjernvarme/blokvarme | AZ12: - | BA12: (UDFASES) Bygningen har ingen supplerende varme | BB12: 528 m2 | BC12: 782.31999 | BD12: 1127.2761 | BE12: 409.06058 | BF12: 305.7877 | BG12: E | BH12: Latinerkvarteret
A13: Klostergade 10, 2. th, 8000 Aarhus C | B13: 5595000 | C13: 44216 | D13: 7 | E13: 161 | G13: 34751.553 | H13: https://www.dingeo.dk/adresse/8000-Aarhus-C/Klostergade-10/2-th | I13: 12 | J13: 0a3f50c3-6b47-32b8-e044-0003ba298018 | K13: Klostergade | L13: 10 | M13: 2 | N13: th | O13: 8000 | P13: Aarhus C | Q13: 1080a | R13: 252242 | S13: 575086.19 | T13: 6224437.5 | U13: 56.159031 | V13: 10.208928 | W13: 1km_6224_575 | X13: Aarhus Domsogn | Y13: Aarhus Øst | Z13: Byzone | AA13: 3.6 | AB13: DOKK1 | AC13: 0 | AD13: 4 | AE13: Meget lav | AF13: 12 - 18 | AG13: Afstand: 1,10 km | AH13: Afstand: 12,00 km | AI13: ✓Asbest | AJ13: !PCB | AK13: !Tungmetaller | AL13: Bolig i etageejendom, flerfamiliehus eller to-familiehus | AM13: Egentlig beboelseslejlighed (boligenhed med eget køkken) | AN13: 1898 | AO13: - | AP13: - | AQ13: Privatpersoner eller interessentskab | AR13: Eget køkken med afløb | AS13: 4 | AT13: 2 | AU13: 1 | AV13: 7 | AW13: Mursten | AX13: Tagpap med stor hældning | AY13: Fjernvarme/blokvarme | AZ13: - | BA13: (UDFASES) Bygningen har ingen supplerende varme | BB13: 1063 m2 | BC13: 691.71437 | BD13: 1006.1633 | BE13: 287.49895 | BF13: 320.00816 | BG13: F | BH13: Latinerkvarteret
A14: Vestergade 15C, 1. tv, 8000 Aarhus C | B14: 3250000 | C14: 44216 | D14: 2 | E14: 71 | F14: -1 | G14: 45774.648 | H14: https://www.dingeo.dk/adresse/8000-Aarhus-C/Vestergade-15C/1-tv | I14: 13 | J14: c38d820c-2c58-485e-ae45-c59c24b07ec5 | K14: Vestergade | L14: 15C | M14: 1 | N14: tv | O14: 8000 | P14: Aarhus C | Q14: 399d | R14: 989945 | S14: 574832.25 | T14: 6224239 | U14: 56.157288 | V14: 10.204785 | W14: 1km_6224_574 | X14: Vor Frue | Y14: Aarhus Øst | Z14: Byzone | AA14: 3.4 | AB14: Rådhushallen | AC14: 0 | AD14: 1 | AE14: Meget lav | AF14: 12 - 18 | AG14: Afstand: 1,24 km | AH14: Afstand: 12,00 km | AI14: ✓Asbest | AJ14: ✓PCB | AK14: !Tungmetaller | AL14: Bolig i etageejendom, flerfamiliehus eller to-familiehus | AM14: Egentlig beboelseslejlighed (boligenhed med eget køkken) | AN14: 2018 | AO14: - | AP14: - | AQ14: Privatpersoner eller interessentskab | AR14: Eget køkken med afløb | AS14: 4 | AT14: 1 | AU14: 1 | AV14: 2 | AW14: Betonelementer | AX14: Tagpap med lille hældning | AY14: Fjernvarme/blokvarme | AZ14: - | BA14: (UDFASES) Bygningen har ingen supplerende varme | BB14: 749 m2 | BC14: 683.23595 | BD14: 776.78071 | BE14: 123.57538 | BF14: 547.8823 | BG14: A2010 | BH14: Indreby
A15: Rådmand Liisbergs Gade 3, 4. tv, 8000 Aarhus C | B15: 3299000 | C15: 44215 | D15: 3 | E15: 72 | G15: 45819.444 | H15: https://www.dingeo.dk/adresse/8000-Aarhus-C/Rådmand-Liisbergs-Gade-3/4-tv | I15: 14 | J15: 0a3f50c4-05cb-32b8-e044-0003ba298018 | K15: Rådmand Liisbergs Gade | L15: 3 | M15: 4 | N15: tv | O15: 8000 | P15: Aarhus C | Q15: 924d | R15: 397747 | S15: 575370.37 | T15: 6224674.5 | U15: 56.161115 | V15: 10.21357 | W15: 1km_6224_575 | X15: Aarhus Domsogn | Y15: Aarhus Øst | Z15: Byzone | AA15: 4.3 | AB15: DOKK1 | AC15: 0 | AD15: 1 | AE15: Meget lav | AF15: 12 - 18 | AG15: Afstand: 1,04 km | AH15: Afstand: 12,00 km | AI15: ✓Asbest | AJ15: !PCB | AK15: !Tungmetaller | AL15: Bolig i etageejendom, flerfamiliehus eller to-familiehus | AM15: Egentlig beboelseslejlighed (boligenhed med eget køkken) | AN15: 1928 | AO15: - | AP15: - | AQ15: Privatpersoner eller interessentskab | AR15: Eget køkken med afløb | AS15: 5 | AT15: 1 | AU15: 1 | AV15: 3 | AW15: Mursten | AX15: Tegl | AY15: Fjernvarme/blokvarme | AZ15: - | BA15: (UDFASES) Bygningen har ingen supplerende varme | BB15: 665 m2 | BC15: 873.50776 | BD15: 1323.4869 | BE15: 646.6004 | BF15: 115.45009 | BG15: F | BH15: Trøjborg
A16: Borggade 7, 3. th, 8000 Aarhus C | B16: 2242000 | C16: 44213 | D16: 3 | E16: 100 | G16: 22420 | H16: https://www.dingeo.dk/adresse/8000-Aarhus-C/Borggade-7/3-th | I16: 15 | J16: 0a3f50c2-8736-32b8-e044-0003ba298018 | K16: Borggade | L16: 7 | M16: 3 | N16: th | O16: 8000 | P16: Aarhus C | Q16: 1081f | R16: 36965 | S16: 575066.44 | T16: 6224522 | U16: 56.159793 | V16: 10.208634 | W16: 1km_6224_575 | X16: Aarhus Domsogn | Y16: Aarhus Øst | Z16: Byzone | AA16: 3.8 | AB16: DOKK1 | AC16: 0 | AD16: 4 | AE16: Meget lav | AF16: 12 - 18 | AG16: Afstand: 1,17 km | AH16: Afstand: 12,00 km | AI16: ✓Asbest | AJ16: !PCB | AK16: !Tungmetaller | AL16: Bolig i etageejendom, flerfamiliehus eller to-familiehus | AM16: Egentlig beboelseslejlighed (boligenhed med eget køkken) | AN16: 1934 | AO16: - | AP16: - | AQ16: Privatpersoner eller interessentskab | AR16: Eget køkken med afløb | AS16: 5 | AT16: 1 | AU16: 1 | AV16: 3 | AW16: Mursten | AX16: Tegl | AY16: Fjernvarme/blokvarme | AZ16: - | BA16: (UDFASES) Bygningen har ingen supplerende varme | BB16: 904 m2 | BC16: 777.33522 | BD16: 1083.9647 | BE16: 356.28308 | BF16: 361.47559 | BG16: C | BH16: Latinerkvarteret
A17: Schleppegrellsgade 26, 4, 8000 Aarhus C | B17: 2100000 | C17: 44213 | D17: 2 | E17: 51 | F17: -2 | G17: 41176.471 | H17: https://www.dingeo.dk/adresse/8000-Aarhus-C/Schleppegrellsgade-26/4 | I17: 16 | J17: 0a3f50c4-0f5e-32b8-e044-0003ba298018 | K17: Schleppegrellsgade | L17: 26 | M17: 4 | O17: 8000 | P17: Aarhus C | Q17: 801o | R17: 404891 | S17: 574067.25 | T17: 6223175 | U17: 56.147849 | V17: 10.192175 | W17: 1km_6223_574 | X17: Sankt Lukas | Y17: Aarhus Syd | Z17: Byzone | AA17: 11.9 | AB17: Lokalcenter Fr.Bjerg/Langenæs | AC17: 1 | AD17: 1 | AE17: Meget lav | AF17: 12 - 18 | AG17: Afstand: 1,37 km | AH17: Afstand: 11,00 km | AI17: ✓Asbest | AJ17: !PCB | AK17: !Tungmetaller | AL17: Bolig i etageejendom, flerfamiliehus eller to-familiehus | AM17: Egentlig beboelseslejlighed (boligenhed med eget køkken) | AN17: 1901 | AO17: - | AP17: - | AQ17: Privatpersoner eller interessentskab | AR17: Eget køkken med afløb | AS17: 4 | AT17: 1 | AU17: 1 | AV17: 2 | AW17: Mursten | AX17: Tegl | AY17: Fjernvarme/blokvarme | AZ17: - | BA17: (UDFASES) Bygningen har ingen supplerende varme | BB17: 224 m2 | BC17: 1432.0721 | BD17: 821.35604 | BE17: 1338.3697 | BF17: 1331.0191 | BG17: D | BH17: Frederiksbjerg
A18: Jægergårdsgade 31, 2, 8000 Aarhus C | B18: 1775000 | C18: 44212 | D18: 1 | E18: 35 | F18: -3 | G18: 50714.286 | H18: https://www.dingeo.dk/adresse/8000-Aarhus-C/Jægergårdsgade-31/2 | I18: 17 | J18: 0a3f50c3-5406-32b8-e044-0003ba298018 | K18: Jægergårdsgade | L18: 31 | M18: 2 | O18: 8000 | P18: Aarhus C | Q18: 39f | R18: 818378 | S18: 574465.19 | T18: 6223217.5 | U18: 56.148169 | V18: 10.198591 | W18: 1km_6223_574 | X18: Sankt Pauls | Y18: Aarhus Øst | Z18: Byzone | AA18: 15.8 | AB18: Rådhushallen | AC18: 1 | AD18: 1 | AE18: Meget lav | AF18: 12 - 18 | AG18: Afstand: 986 meter | AH18: Afstand: 11,00 km | AI18: ✓Asbest | AJ18: !PCB | AK18: !Tungmetaller | AL18: Bolig i etageejendom, flerfamiliehus eller to-familiehus | AM18: Egentlig beboelseslejlighed (boligenhed med eget køkken) | AN18: 1875 | AO18: 1985 | AP18: - | AQ18: Aktie-, anpart- eller andet selskab (undtagen interessent­skab) | AR18: Eget køkken med afløb | AS18: 2 | AT18: 1 | AU18: 1 | AV18: 1 | AW18: Mursten | AX18: Tegl | AY18: Elvarme | AZ18: Elektricitet | BA18: (UDFASES) Bygningen har ingen supplerende varme | BB18: 88 m2 | BC18: 1064.97 | BD18: 445.59996 | BE18: 1081.3219 | BF18: 948.18644 | BG18: E | BH18: Frederiksbjerg
A19: Tøndergade 84, 1. th, 8000 Aarhus C | B19: 2125000 | C19: 44212 | D19: 3 | E19: 76 | F19: -5 | G19: 27960.526 | H19: https://www.dingeo.dk/adresse/8000-Aarhus-C/Tøndergade-84/1-th | I19: 18 | J19: 0a3f50c4-9320-32b8-e044-0003ba298018 | K19: Tøndergade | L19: 84 | M19: 1 | N19: th | O19: 8000 | P19: Aarhus C | Q19: 727e | R19: 518412 | S19: 573395.75 | T19: 6222352.5 | U19: 56.140565 | V19: 10.181143 | W19: 1km_6222_573 | X19: Langenæs | Y19: Aarhus Syd | Z19: Byzone | AA19: 15.2 | AB19: Lokalcenter Fr.Bjerg/Langenæs | AC19: 0 | AD19: 3 | AE19: Meget lav | AF19: 12 - 18 | AG19: Afstand: 2,12 km | AH19: Afstand: 10,00 km | AI19: !Asbest | AJ19: !PCB | AK19: !Tungmetaller | AL19: Bolig i etageejendom, flerfamiliehus eller to-familiehus | AM19: Egentlig beboelseslejlighed (boligenhed med eget køkken) | AN19: 1957 | AO19: - | AP19: - | AQ19: Privatpersoner eller interessentskab | AR19: Eget køkken med afløb | AS19: 3 | AT19: 1 | AU19: 1 | AV19: 3 | AW19: Mursten | AX19: Tegl | AY19: Fjernvarme/blokvarme | AZ19: - | BA19: (UDFASES) Bygningen har ingen supplerende varme | BB19: 931 m2 | BC19: 2435.748 | BD19: 1817.7776 | BE19: 2399.104 | BF19: 1834.6819 | BG19: D | BH19: Langenæs
A20: Åhusene 11, 7. 1, 8000 Aarhus C | B20: 3150000 | C20: 44210 | D20: 3 | E20: 69 | G20: 45652.174 | H20: https://www.dingeo.dk/adresse/8000-Aarhus-C/Åhusene-11/7-1 | I20: 19 | J20: b71394fa-2f86-424e-9f6b-74e279c94d76 | K20: Åhusene | L20: 11 | M20: 7 | N20: 1 | O20: 8000 | P20: Aarhus C | Q20: 2126au | R20: 986230 | S20: 573713.38 | T20: 6223732.5 | U20: 56.152912 | V20: 10.186635 | W20: 1km_6223_573 | X20: Vor Frue | Y20: Aarhus Øst | Z20: Byzone | AA20: 3 | AB20: Rådhushallen | AC20: 1 | AD20: 3 | AE20: Meget lav | AF20: 12 - 18 | AG20: Afstand: 1,89 km | AH20: Afstand: 11,00 km | AI20: ✓Asbest | AJ20: ✓PCB | AK20: !Tungmetaller | AL20: Bolig i etageejendom, flerfamiliehus eller to-familiehus | AM20: Egentlig beboelseslejlighed (boligenhed med eget køkken) | AN20: 2014 | AO20: - | AP20: - | AQ20: Privatpersoner eller interessentskab | AR20: Eget køkken med afløb | AS20: 10 | AT20: 1 | AU20: 1 | AV20: 3 | AW20: Mursten | AX20: Tagpap med stor hældning | AY20: Fjernvarme/blokvarme | AZ20: - | BA20: (UDFASES) Bygningen har ingen supplerende varme | BB20: 3020 m2 | BC20: 1642.5348 | BD20: 1154.7191 | BE20: 1310.1993 | BF20: 1671.7428 | BG20: B | BH20: Ceresbyen
A21: Augustenborggade 5, 5. tv, 8000 Aarhus C | B21: 2595000 | C21: 44210 | D21: 2 | E21: 59 | G21: 43983.051 | H21: https://www.dingeo.dk/adresse/8000-Aarhus-C/Augustenborggade-5/5-tv | I21: 20 | J21: 29e5cd02-18d6-680f-e044-0003ba298018 | K21: Augustenborggade | L21: 5 | M21: 5 | N21: tv | O21: 8000 | P21: Aarhus C | Q21: 716 | R21: 16603 | S21: 573619.25 | T21: 6223035.5 | U21: 56.146666 | V21: 10.184928 | W21: 1km_6223_573 | X21: Langenæs | Y21: Aarhus Syd | Z21: Byzone | AA21: 16.3 | AB21: Lokalcenter Fr.Bjerg/Langenæs | AC21: 0 | AD21: 1 | AE21: Meget lav | AF21: 12 - 18 | AG21: Afstand: 1,81 km | AH21: Afstand: 10,00 km | AI21: ✓Asbest | AJ21: !PCB | AK21: !Tungmetaller | AL21: Bolig i etageejendom, flerfamiliehus eller to-familiehus | AM21: Egentlig beboelseslejlighed (boligenhed med eget køkken) | AN21: 1938 | AO21: - | AP21: - | AQ21: Privatpersoner eller interessentskab | AR21: Eget køkken med afløb | AS21: 5 | AT21: 1 | AU21: 1 | AV21: 2 | AW21: Mursten | AX21: Tegl | AY21: Fjernvarme/blokvarme | AZ21: - | BA21: (UDFASES) Bygningen har ingen supplerende varme | BB21: 635 m2 | BC21: 1896.464 | BD21: 1289.2713 | BE21: 1753.8478 | BF21: 1763.1847 | BG21: D | BH21: Langenæs
A22: Joh. Baunes Plads 18, 2. tv, 8000 Aarhus C | B22: 3760000 | C22: 44209 | D22: 3 | E22: 98 | F22: -2 | G22: 38367.347 | H22: https://www.dingeo.dk/adresse/8000-Aarhus-C/Joh.-Baunes-Plads-18/2-tv | I22: 21 | J22: 0a3f50c3-4f11-32b8-e044-0003ba298018 | K22: Joh. Baunes Plads | L22: 18 | M22: 2 | N22: tv | O22: 8000 | P22: Aarhus C | Q22: 526 | R22: 224745 | S22: 574185.37 | T22: 6222367.5 | U22: 56.140577 | V22: 10.193851 | W22: 1km_6222_574 | X22: Sankt Lukas | Y22: Aarhus Syd | Z22: Byzone | AA22: 16.4 | AB22: Frederiksbjerg Hallerne | AC22: 1 | AD22: 1 | AE22: Meget lav | AF22: 12 - 18 | AG22: Afstand: 1,35 km | AH22: Afstand: 10,00 km | AI22: ✓Asbest | AJ22: !PCB | AK22: !Tungmetaller | AL22: Bolig i etageejendom, flerfamiliehus eller to-familiehus | AM22: Egentlig beboelseslejlighed (boligenhed med eget køkken) | AN22: 1933 | AO22: 2007 | AP22: - | AQ22: Privatpersoner eller interessentskab | AR22: Eget køkken med afløb | AS22: 5 | AT22: 1 | AU22: 1 | AV22: 3 | AW22: Mursten | AX22: Tegl | AY22: Fjernvarme/blokvarme | AZ22: - | BA22: (UDFASES) Bygningen har ingen supplerende varme | BB22: 860 m2 | BC22: 1850.5732 | BD22: 1274.1095 | BE22: 1971.2268 | BF22: 1093.7649 | BG22: C | BH22: Langenæs
A23: Åhusene 7, 2. 3, 8000 Aarhus C | B23: 2500000 | C23: 44209 | D23: 2 | E23: 52 | F23: -4 | G23: 48076.923 | H23: https://www.dingeo.dk/adresse/8000-Aarhus-C/Åhusene-7/2-3 | I23: 22 | J23: b1355a34-b75a-4842-9656-701ff36f67d8 | K23: Åhusene | L23: 7 | M23: 2 | N23: 3 | O23: 8000 | P23: Aarhus C | Q23: 2126ar | R23: 986227 | S23: 573786.44 | T23: 6223713.5 | U23: 56.15273 | V23: 10.187806 | W23: 1km_6223_573 | X23: Vor Frue | Y23: Aarhus Øst | Z23: Byzone | AA23: 2.9 | AB23: Rådhushallen | AC23: 1 | AD23: 3 | AE23: Meget lav | AF23: 12 - 18 | AG23: Afstand: 1,82 km | AH23: Afstand: 11,00 km | AI23: ✓Asbest | AJ23: ✓PCB | AK23: !Tungmetaller | AL23: Bolig i etageejendom, flerfamiliehus eller to-familiehus | AM23: Egentlig beboelseslejlighed (boligenhed med eget køkken) | AN23: 2013 | AO23: - | AP23: - | AQ23: Privatpersoner eller interessentskab | AR23: Eget køkken med afløb | AS23: 10 | AT23: 1 | AU23: 1 | AV23: 2 | AW23: Mursten | AX23: Tagpap med stor hældning | AY23: Fjernvarme/blokvarme | AZ23: - | BA23: (UDFASES) Bygningen har ingen supplerende varme | BB23: 3020 m2 | BC23: 1570.6307 | BD23: 1079.3809 | BE23: 1249.1526 | BF23: 1601.5659 | BG23: B | BH23: Ceresbyen
A24: Valdemars Have 26, 5. tv, 8000 Aarhus C | B24: 7650000 | C24: 44209 | D24: 3 | E24: 119 | G24: 64285.714 | H24: https://www.dingeo.dk/adresse/8000-Aarhus-C/Valdemars-Have-26/5-tv | I24: 23 | J24: 12da5d00-555f-4a56-b512-9ed26b28afb7 | K24: Valdemars Have | L24: 26 | M24: 5 | N24: tv | O24: 8000 | P24: Aarhus C | Q24: 1294v | R24: 996487 | S24: 574378.73 | T24: 6223585.2 | U24: 56.151486 | V24: 10.197302 | W24: 1km_6223_574 | X24: Vor Frue | Y24: Aarhus Øst | Z24: Byzone | AA24: 13.6 | AB24: Rådhushallen | AC24: 1 | AD24: 1 | AE24: Meget lav | AF24: 12 - 18 | AG24: Afstand: 1,22 km | AH24: Afstand: 11,00 km | AI24: ✓Asbest | AJ24: ✓PCB | AK24: !Tungmetaller | AL24: Bolig i etageejendom, flerfamiliehus eller to-familiehus | AM24: Egentlig beboelseslejlighed (boligenhed med eget køkken) | AN24: 2019 | AO24: - | AP24: - | AQ24: Privatpersoner eller interessentskab | AR24: Eget køkken med afløb | AS24: 6 | AT24: 1 | AU24: 1 | AV24: 3 | AW24: Mursten | AX24: Levende tage | AY24: Fjernvarme/blokvarme | AZ24: - | BA24: - | BB24: 1860 m2 | BC24: 1000.648 | BD24: 474.79242 | BE24: 825.42834 | BF24: 1051.4954 | BG24: A2015 | BH24: Indreby
A25: Bernhardt Jensens Boulevard 111, 1. 2, 8000 Aarhus C | B25: 2970000 | C25: 44208 | D25: 2 | E25: 68 | F25: -1 | G25: 43676.471 | H25: https://www.dingeo.dk/adresse/8000-Aarhus-C/Bernhardt-Jensens-Boulevard-111/1-2 | I25: 24 | J25: b2a1cbfe-1682-40de-a8b1-95953faa2feb | K25: Bernhardt Jensens Boulevard | L25: 111 | M25: 1 | N25: 2 | O25: 8000 | P25: Aarhus C | Q25: 2148em | R25: 989931 | S25: 576178.62 | T25: 6225320.6 | U25: 56.16679 | V25: 10.226765 | W25: 1km_6225_576 | X25: Aarhus Domsogn | Y25: Aarhus Øst | Z25: Byzone | AA25: -4 | AB25: DOKK1 | AC25: 1 | AD25: 1 | AE25: Meget lav | AF25: 12 - 18 | AG25: Afstand: 1,29 km | AH25: Afstand: 12,00 km | AI25: ✓Asbest | AJ25: ✓PCB | AK25: !Tungmetaller | AL25: Bolig i etageejendom, flerfamiliehus eller to-familiehus | AM25: Egentlig beboelseslejlighed (boligenhed med eget køkken) | AN25: 2017 | AO25: - | AP25: - | AQ25: Privatpersoner eller interessentskab | AR25: Eget køkken med afløb | AS25: 10 | AT25: 1 | AU25: 1 | AV25: 2 | AW25: Betonelementer | AX25: Tagpap med lille hældning | AY25: Fjernvarme/blokvarme | AZ25: - | BA25: (UDFASES) Bygningen har ingen supplerende varme | BB25: 9636 m2 | BC25: 1726.2671 | BD25: 2289.7314 | BE25: 1673.7504 | BF25: 251.94596 | BG25: NA | BH25: Århus Ø
A26: Rosenkrantzgade 12B, 4, 8000 Aarhus C | B26: 2510000 | C26: 44208 | D26: 2 | E26: 54 | F26: -3 | G26: 46481.481 | H26: https://www.dingeo.dk/adresse/8000-Aarhus-C/Rosenkrantzgade-12B/4 | I26: 25 | J26: d0709be8-f72b-4d2f-9851-990f6e32e7ff | K26: Rosenkrantzgade | L26: 12B | M26: 4 | O26: 8000 | P26: Aarhus C | Q26: 1375 | R26: 384564 | S26: 574975.73 | T26: 6223679.5 | U26: 56.152239 | V26: 10.206937 | W26: 1km_6223_574 | X26: Aarhus Domsogn | Y26: Aarhus Øst | Z26: Byzone | AA26: 7.8 | AB26: Rådhushallen | AC26: 0 | AD26: 1 | AE26: Meget lav | AF26: 12 - 18 | AG26: Afstand: 861 meter | AH26: Afstand: 12,00 km | AI26: ✓Asbest | AJ26: !PCB | AK26: !Tungmetaller | AL26: Bolig i etageejendom, flerfamiliehus eller to-familiehus | AM26: Egentlig beboelseslejlighed (boligenhed med eget køkken) | AN26: 1875 | AO26: 2013 | AP26: - | AQ26: Privatpersoner eller interessentskab | AR26: Eget køkken med afløb | AS26: 4 | AT26: 1 | AU26: 1 | AV26: 2 | AW26: Mursten | AX26: Tegl | AY26: Fjernvarme/blokvarme | AZ26: - | BA26: (UDFASES) Bygningen har ingen supplerende varme | BB26: 328 m2 | BC26: 400.18584 | BD26: 256.91697 | BE26: 508.61035 | BF26: 450.27114 | BG26: E | BH26: Indreby
A27: Grønnegade 87, 4. th, 8000 Aarhus C | B27: 2295000 | C27: 44206 | D27: 2 | E27: 52 | G27: 44134.615 | H27: https://www.dingeo.dk/adresse/8000-Aarhus-C/Grønnegade-87/4-th | I27: 26 | J27: 0a3f50c2-fb52-32b8-e044-0003ba298018 | K27: Grønnegade | L27: 87 | M27: 4 | N27: th | O27: 8000 | P27: Aarhus C | Q27: 1940f | R27: 148771 | S27: 574562.44 | T27: 6224538.5 | U27: 56.16002 | V27: 10.200526 | W27: 1km_6224_574 | X27: Vor Frue | Y27: Aarhus Øst | Z27: Byzone | AA27: 9.6 | AB27: Rådhushallen | AC27: 1 | AD27: 4 | AE27: Meget lav | AF27: 12 - 18 | AG27: Afstand: 1,62 km | AH27: Afstand: 12,00 km | AI27: ✓Asbest | AJ27: !PCB | AK27: !Tungmetaller | AL27: Bolig i etageejendom, flerfamiliehus eller to-familiehus | AM27: Egentlig beboelseslejlighed (boligenhed med eget køkken) | AN27: 1917 | AO27: 2014 | AP27: - | AQ27: Privatpersoner eller interessentskab | AR27: Eget køkken med afløb | AS27: 5 | AT27: 1 | AU27: 1 | AV27: 2 | AW27: Mursten | AX27: Tegl | AY27: Fjernvarme/blokvarme | AZ27: - | BA27: (UDFASES) Bygningen har ingen supplerende varme | BB27: 1395 m2 | BC27: 1083.442 | BD27: 1110.9497 | BE27: 518.64965 | BF27: 851.33794 | BG27: F | BH27: Øgadekvarteret
A28: Odensegade 42, 5, 8000 Aarhus C | B28: 4000000 | C28: 44204 | D28: 3 | E28: 116 | G28: 34482.759 | H28: https://www.dingeo.dk/adresse/8000-Aarhus-C/Odensegade-42/5 | I28: 27 | J28: cacd4460-4739-4881-a611-4d56c3a72caa | K28: Odensegade | L28: 42 | M28: 5 | O28: 8000 | P28: Aarhus C | Q28: 742m | R28: 347979 | S28: 574568.06 | T28: 6222894 | U28: 56.145247 | V28: 10.200156 | W28: 1km_6222_574 | X28: Sankt Pauls | Y28: Aarhus Syd | Z28: Byzone | AA28: 20.5 | AB28: Frederiksbjerg Hallerne | AC28: 0 | AD28: 5 | AE28: Meget lav | AF28: 12 - 18 | AG28: Afstand: 837 meter | AH28: Afstand: 11,00 km | AI28: ✓Asbest | AJ28: !PCB | AK28: !Tungmetaller | AL28: Bolig i etageejendom, flerfamiliehus eller to-familiehus | AM28: Egentlig beboelseslejlighed (boligenhed med eget køkken) | AN28: 1907 | AO28: - | AP28: - | AQ28: Aktie-, anpart- eller andet selskab (undtagen interessent­skab) | AR28: Eget køkken med afløb | AS28: 5 | AT28: 1 | AU28: 1 | AV28: 3 | AW28: Mursten | AX28: Tegl | AY28: Fjernvarme/blokvarme | AZ28: - | BA28: (UDFASES) Bygningen har ingen supplerende varme | BB28: 962 m2 | BC28: 1201.7307 | BD28: 629.08741 | BE28: 1346.737 | BF28: 815.00534 | BG28: D | BH28: Frederiksbjerg
A29: Janus La Cours Gade 20, 2. tv, 8000 Aarhus C | B29: 3499000 | C29: 44203 | D29: 3 | E29: 83 | G29: 42156.627 | H29: https://www.dingeo.dk/adresse/8000-Aarhus-C/Janus-La-Cours-Gade-20/2-tv | I29: 28 | J29: 0a3f50c3-4564-32b8-e044-0003ba298018 | K29: Janus La Cours Gade | L29: 20 | M29: 2 | N29: tv | O29: 8000 | P29: Aarhus C | Q29: 1286a | R29: 527489 | S29: 574304.06 | T29: 6224218.5 | U29: 56.157186 | V29: 10.196277 | W29: 1km_6224_574 | X29: Vor Frue | Y29: Aarhus Øst | Z29: Byzone | AA29: 3.7 | AB29: Rådhushallen | AC29: 0 | AD29: 1 | AE29: Meget lav | AF29: 12 - 18 | AG29: Afstand: 1,70 km | AH29: Afstand: 12,00 km | AI29: ✓Asbest | AJ29: ✓PCB | AK29: !Tungmetaller | AL29: Bolig i etageejendom, flerfamiliehus eller to-familiehus | AM29: Egentlig beboelseslejlighed (boligenhed med eget køkken) | AN29: 1984 | AO29: - | AP29: - | AQ29: Privatpersoner eller interessentskab | AR29: Eget køkken med afløb | AS29: 4 | AT29: 1 | AU29: 1 | AV29: 3 | AW29: Mursten | AX29: Tegl | AY29: Fjernvarme/blokvarme | AZ29: - | BA29: - | BB29: 3525 m2 | BC29: 1131.4184 | BD29: 925.31505 | BE29: 640.07022 | BF29: 1070.7602 | BG29: C | BH29: Indreby
A30: Banegårdsgade 31, 3, 8000 Aarhus C | B30: 1795000 | C30: 44202 | D30: 2 | E30: 50 | G30: 35900 | H30: https://www.dingeo.dk/adresse/8000-Aarhus-C/Banegårdsgade-31/3 | I30: 29 | J30: 0a3f50c2-7576-32b8-e044-0003ba298018 | K30: Banegårdsgade | L30: 31 | M30: 3 | O30: 8000 | P30: Aarhus C | Q30: 1321l | R30: 23502 | S30: 574671.69 | T30: 6223482 | U30: 56.150513 | V30: 10.201988 | W30: 1km_6223_574 | X30: Vor Frue | Y30: Aarhus Øst | Z30: Byzone | AA30: 13.3 | AB30: Rådhushallen | AC30: 0 | AD30: 5 | AE30: Meget lav | AF30: 12 - 18 | AG30: Afstand: 917 meter | AH30: Afstand: 11,00 km | AI30: ✓Asbest | AJ30: !PCB | AK30: !Tungmetaller | AL30: Bolig i etageejendom, flerfamiliehus eller to-familiehus | AM30: Egentlig beboelseslejlighed (boligenhed med eget køkken) | AN30: 1877 | AO30: 1990 | AP30: - | AQ30: Privatpersoner eller interessentskab | AR30: Eget køkken med afløb | AS30: 3 | AT30: 1 | AU30: 1 | AV30: 2 | AW30: Mursten | AX30: Tegl | AY30: Fjernvarme/blokvarme | AZ30: - | BA30: (UDFASES) Bygningen har ingen supplerende varme | BB30: 203 m2 | BC30: 755.421 | BD30: 167.3889 | BE30: 755.96294 | BF30: 756.83296 | BG30: D | BH30: Indreby
A31: Graven 3A, st, 8000 Aarhus C | B31: 16000000 | C31: 44202 | D31: 2 | E31: 115 | G31: 139130.43 | H31: https://www.dingeo.dk/adresse/8000-Aarhus-C/Graven-3A/st | I31: 30 | J31: 0a3f50c2-f003-32b8-e044-0003ba298018 | K31: Graven | L31: 3A | M31: st | O31: 8000 | P31: Aarhus C | Q31: 712c | R31: 588267 | S31: 575244.38 | T31: 6224336.5 | U31: 56.158099 | V31: 10.211446 | W31: 1km_6224_575 | X31: Aarhus Domsogn | Y31: Aarhus Øst | Z31: Byzone | AA31: 4.6 | AB31: DOKK1 | AC31: 1 | AD31: 1 | AE31: Meget lav | AF31: 12 - 18 | AG31: Afstand: 912 meter | AH31: Afstand: 12,00 km | AI31: ✓Asbest | AJ31: ✓PCB | AK31: !Tungmetaller | AL31: Bolig i etageejendom, flerfamiliehus eller to-familiehus | AM31: Egentlig beboelseslejlighed (boligenhed med eget køkken) | AN31: 1989 | AO31: - | AP31: - | AQ31: Aktie-, anpart- eller andet selskab (undtagen interessent­skab) | AR31: Eget køkken med afløb | AS31: 2 | AT31: 1 | AU31: 1 | AV31: 2 | AW31: Mursten | AX31: Tegl | AY31: Fjernvarme/blokvarme | AZ31: - | BA31: (UDFASES) Bygningen har ingen supplerende varme | BB31: 454 m2 | BC31: 547.21348 | BD31: 963.6298 | BE31: 334.37511 | BF31: 146.10947 | BG31: C | BH31: Latinerkvarteret
A32: Stadion Allé 15, 5. th, 8000 Aarhus C | B32: 3108000 | C32: 44202 | D32: 3 | E32: 77 | F32: -3 | G32: 40363.636 | H32: https://www.dingeo.dk/adresse/8000-Aarhus-C/Stadion-Allé-15/5-th | I32: 31 | J32: 0a3f50c4-5028-32b8-e044-0003ba298018 | K32: Stadion Allé | L32: 15 | M32: 5 | N32: th | O32: 8000 | P32: Aarhus C | Q32: 741dl | R32: 455550 | S32: 574217.06 | T32: 6222634.5 | U32: 56.142971 | V32: 10.194436 | W32: 1km_6222_574 | X32: Sankt Lukas | Y32: Aarhus Syd | Z32: Byzone | AA32: 17.5 | AB32: Frederiksbjerg Hallerne | AC32: 1 | AD32: 1 | AE32: Meget lav | AF32: 12 - 18 | AG32: Afstand: 1,23 km | AH32: Afstand: 10,00 km | AI32: ✓Asbest | AJ32: !PCB | AK32: !Tungmetaller | AL32: Bolig i etageejendom, flerfamiliehus eller to-familiehus | AM32: Egentlig beboelseslejlighed (boligenhed med eget køkken) | AN32: 1929 | AO32: - | AP32: - | AQ32: Privatpersoner eller interessentskab | AR32: Eget køkken med afløb | AS32: 5 | AT32: 1 | AU32: 1 | AV32: 3 | AW32: Mursten | AX32: Tegl | AY32: Fjernvarme/blokvarme | AZ32: - | BA32: (UDFASES) Bygningen har ingen supplerende varme | BB32: 759 m2 | BC32: 1630.0982 | BD32: 1034.2683 | BE32: 1714.134 | BF32: 1190.2251 | BG32: D | BH32: Frederiksbjerg
A33: Marselis Boulevard 38, 1. 104, 8000 Aarhus C | B33: 2100000 | C33: 44202 | D33: 2 | E33: 70 | F33: -2 | G33: 30000 | H33: https://www.dingeo.dk/adresse/8000-Aarhus-C/Marselis-Boulevard-38/1-104 | I33: 32 | J33: 0a3f50c3-9df4-32b8-e044-0003ba298018 | K33: Marselis Boulevard | L33: 38 | M33: 1 | N33: 104 | O33: 8000 | P33: Aarhus C | Q33: 741ho | R33: 300832 | S33: 574372.87 | T33: 6222417 | U33: 56.140993 | V33: 10.196882 | W33: 1km_6222_574 | X33: Sankt Lukas | Y33: Aarhus Syd | Z33: Byzone | AA33: 16.4 | AB33: Frederiksbjerg Hallerne | AC33: 0 | AD33: 4 | AE33: Meget lav | AF33: 12 - 18 | AG33: Afstand: 1,16 km | AH33: Afstand: 10,00 km | AI33: !Asbest | AJ33: !PCB | AK33: !Tungmetaller | AL33: Bolig i etageejendom, flerfamiliehus eller to-familiehus | AM33: Egentlig beboelseslejlighed (boligenhed med eget køkken) | AN33: 1966 | AO33: - | AP33: - | AQ33: Privatpersoner eller interessentskab | AR33: Eget køkken med afløb | AS33: 14 | AT33: 1 | AU33: 1 | AV33: 2 | AW33: Betonelementer | AX33: Tagpap med stor hældning | AY33: Fjernvarme/blokvarme | AZ33: - | BA33: (UDFASES) Bygningen har ingen supplerende varme | BB33: 7310 m2 | BC33: 1697.7255 | BD33: 1143.934 | BE33: 1859.9677 | BF33: 946.98878 | BG33: D | BH33: Frederiksbjerg
A34: Skovvejen 46H, 1. 104, 8000 Aarhus C | B34: 1025000 | C34: 44201 | D34: 1 | E34: 30 | F34: -4 | G34: 34166.667 | H34: https://www.dingeo.dk/adresse/8000-Aarhus-C/Skovvejen-46H/1-104 | I34: 33 | J34: 0a3f50c4-3588-32b8-e044-0003ba298018 | K34: Skovvejen | L34: 46H | M34: 1 | N34: 104 | O34: 8000 | P34: Aarhus C | Q34: 1475a | R34: 436211 | S34: 575703.13 | T34: 6225481 | U34: 56.168307 | V34: 10.219156 | W34: 1km_6225_575 | X34: Sankt Johannes | Y34: Aarhus Øst | Z34: Byzone | AA34: 18.8 | AB34: DOKK1 | AC34: 0 | AD34: 1 | AE34: Meget lav | AF34: 12 - 18 | AG34: Afstand: 1,53 km | AH34: Afstand: 12,00 km | AI34: !Asbest | AJ34: !PCB | AK34: !Tungmetaller | AL34: Bolig i etageejendom, flerfamiliehus eller to-familiehus | AM34: Egentlig beboelseslejlighed (boligenhed med eget køkken) | AN34: 1938 | AO34: - | AP34: - | AQ34: Privatpersoner eller interessentskab | AR34: Eget køkken med afløb | AS34: 5 | AT34: 1 | AU34: 1 | AV34: 1 | AW34: Andet materiale | AX34: Tagpap med lille hældning | AY34: Fjernvarme/blokvarme | AZ34: - | BA34: (UDFASES) Bygningen har ingen supplerende varme | BB34: 2020 m2 | BC34: 1714.974 | BD34: 2195.6093 | BE34: 1499.119 | BF34: 172.78778 | BG34: D | BH34: Trøjborg
A35: Frederiks Plads 8, 2. 10, 8000 Aarhus C | B35: 2272800 | C35: 44201 | D35: 2 | E35: 61 | G35: 37259.016 | H35: https://www.dingeo.dk/adresse/8000-Aarhus-C/Frederiks-Plads-8/2-10 | I35: 34 | J35: 8468c49a-488b-466b-aa84-74eeaa7e88e2 | K35: Frederiks Plads | L35: 8 | M35: 2 | N35: 10 | O35: 8000 | P35: Aarhus C | Q35: 2200p | R35: 990071 | S35: 575084.45 | T35: 6223348.1 | U35: 56.149245 | V35: 10.208593 | W35: 1km_6223_575 | X35: Sankt Pauls | Y35: Aarhus Øst | Z35: Byzone | AA35: 3.9 | AB35: Rådhushallen | AC35: 1 | AD35: 1 | AE35: Meget lav | AF35: 12 - 18 | AG35: Afstand: 522 meter | AH35: Afstand: 11,00 km | AI35: ✓Asbest | AJ35: ✓PCB | AK35: !Tungmetaller | AL35: Bolig i etageejendom, flerfamiliehus eller to-familiehus | AM35: Egentlig beboelseslejlighed (boligenhed med eget køkken) | AN35: 2017 | AO35: - | AP35: - | AQ35: Privatpersoner eller interessentskab | AR35: Eget køkken med afløb | AS35: 9 | AT35: 1 | AU35: 1 | AV35: 2 | AW35: Mursten | AX35: Tagpap med stor hældning | AY35: Fjernvarme/blokvarme | AZ35: - | BA35: (UDFASES) Bygningen har ingen supplerende varme | BB35: 5430 m2 | BC35: 528.89222 | BD35: 270.99717 | BE35: 850.6881 | BF35: 326.48775 | BG35: A2015 | BH35: Frederiksbjerg
A36: Marselis Boulevard 28, 2. 2, 8000 Aarhus C | B36: 1300000 | C36: 44200 | D36: 2 | E36: 52 | F36: -7 | G36: 25000 | H36: https://www.dingeo.dk/adresse/8000-Aarhus-C/Marselis-Boulevard-28/2-2 | I36: 35 | J36: 0a3f50c3-9ca3-32b8-e044-0003ba298018 | K36: Marselis Boulevard | L36: 28 | M36: 2 | N36: 2 | O36: 8000 | P36: Aarhus C | Q36: 741hf | R36: 300743 | S36: 574663.37 | T36: 6222511.5 | U36: 56.141796 | V36: 10.201582 | W36: 1km_6222_574 | X36: Sankt Pauls | Y36: Aarhus Syd | Z36: Byzone | AA36: 13.6 | AB36: Frederiksbjerg Hallerne | AC36: 1 | AD36: 3 | AE36: Meget lav | AF36: 12 - 18 | AG36: Afstand: 847 meter | AH36: Afstand: 11,00 km | AI36: !Asbest | AJ36: !PCB | AK36: !Tungmetaller | AL36: Bolig i etageejendom, flerfamiliehus eller to-familiehus | AM36: Egentlig beboelseslejlighed (boligenhed med eget køkken) | AN36: 1959 | AO36: - | AP36: - | AQ36: Privatpersoner eller interessentskab | AR36: Eget køkken med afløb | AS36: 14 | AT36: 1 | AU36: 1 | AV36: 2 | AW36: Betonelementer | AX36: Tagpap med stor hældning | AY36: Fjernvarme/blokvarme | AZ36: - | BA36: (UDFASES) Bygningen har ingen supplerende varme | BB36: 6784 m2 | BC36: 1464.144 | BD36: 966.79695 | BE36: 1699.1301 | BF36: 760.12013 | BG36: D | BH36: Frederiksbjerg
A37: Hans Schourups Gade 8, 1. th, 8000 Aarhus C | B37: 2400000 | C37: 44200 | D37: 2 | E37: 70 | G37: 34285.714 | H37: https://www.dingeo.dk/adresse/8000-Aarhus-C/Hans-Schourups-Gade-8/1-th | I37: 36 | J37: 0a3f50c3-0aa8-32b8-e044-0003ba298018 | K37: Hans Schourups Gade | L37: 8 | M37: 1 | N37: th | O37: 8000 | P37: Aarhus C | Q37: 564 | R37: 159005 | S37: 574040.81 | T37: 6222481 | U37: 56.141619 | V37: 10.191557 | W37: 1km_6222_574 | X37: Sankt Lukas | Y37: Aarhus Syd | Z37: Byzone | AA37: 18.7 | AB37: Frederiksbjerg Hallerne | AC37: 0 | AD37: 1 | AE37: Meget lav | AF37: 12 - 18 | AG37: Afstand: 1,45 km | AH37: Afstand: 10,00 km | AI37: ✓Asbest | AJ37: !PCB | AK37: !Tungmetaller | AL37: Bolig i etageejendom, flerfamiliehus eller to-familiehus | AM37: Egentlig beboelseslejlighed (boligenhed med eget køkken) | AN37: 1935 | AO37: - | AP37: - | AQ37: Privatpersoner eller interessentskab | AR37: Eget køkken med afløb | AS37: 5 | AT37: 1 | AU37: 1 | AV37: 2 | AW37: Mursten | AX37: Tegl | AY37: Fjernvarme/blokvarme | AZ37: - | BA37: (UDFASES) Bygningen har ingen supplerende varme | BB37: 700 m2 | BC37: 1862.9047 | BD37: 1263.5189 | BE37: 1930.0043 | BF37: 1272.8319 | BG37: C | BH37: Langenæs
A38: Søndre Ringgade 61, 4. tv, 8000 Aarhus C | B38: 2395000 | C38: 44200 | D38: 2 | E38: 75 | G38: 31933.333 | H38: https://www.dingeo.dk/adresse/8000-Aarhus-C/Søndre-Ringgade-61/4-tv | I38: 37 | J38: 0a3f50c4-6e19-32b8-e044-0003ba298018 | K38: Søndre Ringgade | L38: 61 | M38: 4 | N38: tv | O38: 8000 | P38: Aarhus C | Q38: 688 | R38: 484305 | S38: 573746.31 | T38: 6222881 | U38: 56.145258 | V38: 10.18693 | W38: 1km_6222_573 | X38: Langenæs | Y38: Aarhus Syd | Z38: Byzone | AA38: 17.4 | AB38: Lokalcenter Fr.Bjerg/Langenæs | AC38: 1 | AD38: 5 | AE38: Meget lav | AF38: 12 - 18 | AG38: Afstand: 1,68 km | AH38: Afstand: 10,00 km | AI38: ✓Asbest | AJ38: !PCB | AK38: !Tungmetaller | AL38: Bolig i etageejendom, flerfamiliehus eller to-familiehus | AM38: Egentlig beboelseslejlighed (boligenhed med eget køkken) | AN38: 1938 | AO38: - | AP38: - | AQ38: Privatpersoner eller interessentskab | AR38: Eget køkken med afløb | AS38: 5 | AT38: 1 | AU38: 1 | AV38: 2 | AW38: Mursten | AX38: Tegl | AY38: Fjernvarme/blokvarme | AZ38: - | BA38: (UDFASES) Bygningen har ingen supplerende varme | BB38: 1150 m2 | BC38: 1852.8665 | BD38: 1235.1232 | BE38: 1770.985 | BF38: 1636.2895 | BG38: D | BH38: Langenæs
A39: Vestervang 2, kl. 2001, 8000 Aarhus C | B39: 5450000 | C39: 44200 | D39: 3 | E39: 129 | F39: -3 | G39: 42248.062 | H39: https://www.dingeo.dk/adresse/8000-Aarhus-C/Vestervang-2/kl-2001 | I39: 38 | J39: 0a3f50c4-a3e1-32b8-e044-0003ba298018 | K39: Vestervang | L39: 2 | M39: kl | N39: 2001 | O39: 8000 | P39: Aarhus C | Q39: 117up | R39: 529252 | S39: 574196.87 | T39: 6224726 | U39: 56.161761 | V39: 10.194694 | W39: 1km_6224_574 | X39: Sankt Markus | Y39: Aarhus Nord | Z39: Byzone | AA39: 29.8 | AB39: Møllevangskolen | AC39: 0 | AD39: 1 | AE39: Meget lav | AF39: 12 - 18 | AG39: Afstand: 2,03 km | AH39: Afstand: 12,00 km | AI39: !Asbest | AJ39: !PCB | AK39: !Tungmetaller | AL39: Bolig i etageejendom, flerfamiliehus eller to-familiehus | AM39: Egentlig beboelseslejlighed (boligenhed med eget køkken) | AN39: 1970 | AO39: - | AP39: - | AQ39: Privatpersoner eller interessentskab | AR39: Eget køkken med afløb | AS39: 3 | AT39: 2 | AU39: 1 | AV39: 3 | AW39: Betonelementer | AX39: Tagpap med lille hældning | AY39: Fjernvarme/blokvarme | AZ39: - | BA39: (UDFASES) Bygningen har ingen supplerende varme | BB39: 2488 m2 | BC39: 1482.5392 | BD39: 1416.7094 | BE39: 920.5605 | BF39: 1251.8385 | BG39: C | BH39: Vesterbro
A40: Knudrisgade 11, 3, 8000 Aarhus C | B40: 1500000 | C40: 44200 | D40: 1 | E40: 54 | G40: 27777.778 | H40: https://www.dingeo.dk/adresse/8000-Aarhus-C/Knudrisgade-11/3 | I40: 39 | J40: 0a3f50c3-6d6a-32b8-e044-0003ba298018 | K40: Knudrisgade | L40: 11 | M40: 3 | O40: 8000 | P40: Aarhus C | Q40: 1136 | R40: 254261 | S40: 575307 | T40: 6224852.5 | U40: 56.162724 | V40: 10.2126 | W40: 1km_6224_575 | X40: Aarhus Domsogn | Y40: Aarhus Øst | Z40: Byzone | AA40: 6.2 | AB40: DOKK1 | AC40: 0 | AD40: 1 | AE40: Meget lav | AF40: 12 - 18 | AG40: Afstand: 1,21 km | AH40: Afstand: 12,00 km | AI40: ✓Asbest | AJ40: !PCB | AK40: !Tungmetaller | AL40: Bolig i etageejendom, flerfamiliehus eller to-familiehus | AM40: Egentlig beboelseslejlighed (boligenhed med eget køkken) | AN40: 1871 | AO40: 1982 | AP40: - | AQ40: Alment boligselskab | AR40: Eget køkken med afløb | AS40: 3 | AT40: 1 | AU40: 1 | AV40: 1 | AW40: Mursten | AX40: Tegl | AY40: Fjernvarme/blokvarme | AZ40: - | BA40: (UDFASES) Bygningen har ingen supplerende varme | BB40: 188 m2 | BC40: 1052.6583 | BD40: 1466.8866 | BE40: 757.34592 | BF40: 234.91124 | BG40: D | BH40: Trøjborg
...

Sheet Sheet1 (2)
A1: Address | B1: SalesPrice | C1: SalesDate | D1: SqM | E1: PriceSqM | F1: Story | G1: Parish | H1: Height1 | I1: PollingArea | J1: FibreInternet | K1: Noise | L1: Radon | M1: Asbest | N1: PCB | O1: HeavyMetals | P1: ConsAge | Q1: Recon | R1: No.Stories | S1: No.Toilets | T1: No.Bathrooms | U1: No.Rooms | V1: ExteriorWallMaterial | W1: RoofMaterial | X1: HeatingType | Y1: BuildingArea | Z1: DistCitizenService | AA1: DistMainStation | AB1: DistCentrum | AC1: DistCoastline | AD1: EnergyLabel | AE1: Area | AF1: Height2 | AG1: wgs84koordinat_bredde | AH1: wgs84koordinat_længde
A2: Ceresbyen 66, 3. 2, 8000 Aarhus C | B2: 4075149 | C2: 44242 | D2: 96 | E2: 41145.833 | F2: 3 | G2: 7 | H2: 4.5 | I2: 8 | J2: 1 | K2: 3 | L2: 1 | M2: 0 | N2: 0 | O2: 1 | P2: 4 | Q2: 0 | R2: 9 | S2: 1 | T2: 1 | U2: 3 | V2: 2 | W2: 5 | X2: 3 | Y2: 5335 | Z2: 1221.5548 | AA2: 953.59872 | AB2: 755.46827 | AC2: 1183.6876 | AD2: 9 | AE2: 1 | AF2: 7.5 | AG2: =_xlfn.XLOOKUP(A2,Sheet1!A:A,Sheet1!U:U,) -> 56.156688 | AH2: =_xlfn.XLOOKUP(A2,Sheet1!A:A,Sheet1!V:V,) -> 10.194395
A3: Tage-Hansens Gade 7, 5. tv, 8000 Aarhus C | B3: 2176851 | C3: 44237 | D3: 69 | E3: 30579.71 | F3: 5 | G3: 2 | H3: 19.5 | I3: 8 | J3: 0 | K3: 1 | L3: 1 | M3: 1 | N3: 1 | O3: 1 | P3: 76 | Q3: 0 | R3: 6 | S3: 1 | T3: 1 | U3: 2 | V3: 6 | W3: 3 | X3: 3 | Y3: 1203 | Z3: 1857.3143 | AA3: 1506.5493 | AB3: 1391.153 | AC3: 1823.2921 | AD3: 5 | AE3: 8 | AF3: 12.5 | AG3: =_xlfn.XLOOKUP(A3,Sheet1!A:A,Sheet1!U:U,) -> 56.157595 | AH3: =_xlfn.XLOOKUP(A3,Sheet1!A:A,Sheet1!V:V,) -> 10.184184
A4: Ceres Allé 7, 12. 6, 8000 Aarhus C | B4: 2019520 | C4: 44227 | D4: 97 | E4: 20180.412 | F4: 12 | G4: 7 | H4: 4.2 | I4: 8 | J4: 1 | K4: 1 | L4: 1 | M4: 0 | N4: 0 | O4: 1 | P4: 5 | Q4: 0 | R4: 19 | S4: 1 | T4: 1 | U4: 3 | V4: 2 | W4: 5 | X4: 3 | Y4: 17885 | Z4: 1365.8123 | AA4: 960.27174 | AB4: 983.69389 | AC4: 1379.1071 | AD4: 8 | AE4: 1 | AF4: 30 | AG4: =_xlfn.XLOOKUP(A4,Sheet1!A:A,Sheet1!U:U,) -> 56.154591 | AH4: =_xlfn.XLOOKUP(A4,Sheet1!A:A,Sheet1!V:V,) -> 10.191218
A5: Schleppegrellsgade 28, 1. th, 8000 Aarhus C | B5: 1877663 | C5: 44227 | D5: 44 | E5: 41363.636 | F5: 1 | G5: 4 | H5: 11.4 | I5: 3 | J5: 1 | K5: 2 | L5: 1 | M5: 0 | N5: 1 | O5: 1 | P5: 121 | Q5: 0 | R5: 5 | S5: 1 | T5: 0 | U5: 2 | V5: 6 | W5: 3 | X5: 3 | Y5: 546 | Z5: 1431.364 | AA5: 821.59269 | AB5: 1333.9141 | AC5: 1336.0196 | AD5: 3 | AE5: 2 | AF5: 2.5 | AG5: =_xlfn.XLOOKUP(A5,Sheet1!A:A,Sheet1!U:U,) -> 56.147931 | AH5: =_xlfn.XLOOKUP(A5,Sheet1!A:A,Sheet1!V:V,) -> 10.192121
A6: Skovvejen 75, st, 8000 Aarhus C | B6: 2321287 | C6: 44222 | D6: 47 | E6: 47872.34 | F6: 0 | G6: 3 | H6: 10.4 | I6: 1 | J6: 0 | K6: 5 | L6: 1 | M6: 1 | N6: 0 | O6: 1 | P6: 121 | Q6: 1 | R6: 3 | S6: 1 | T6: 1 | U6: 2 | V6: 6 | W6: 4 | X6: 3 | Y6: 162 | Z6: 1511.0946 | AA6: 1989.6368 | AB6: 1296.7259 | AC6: 151.60514 | AD6: 5 | AE6: 7 | AF6: 0 | AG6: =_xlfn.XLOOKUP(A6,Sheet1!A:A,Sheet1!U:U,) -> 56.166575 | AH6: =_xlfn.XLOOKUP(A6,Sheet1!A:A,Sheet1!V:V,) -> 10.217967
A7: Studsgade 28, 1. th, 8000 Aarhus C | B7: 2940297 | C7: 44221 | D7: 77 | E7: 37012.987 | F7: 1 | G7: 8 | H7: 3.7 | I7: 1 | J7: 0 | K7: 3 | L7: 1 | M7: 0 | N7: 1 | O7: 1 | P7: 127 | Q7: 1 | R7: 2 | S7: 1 | T7: 1 | U7: 3 | V7: 6 | W7: 3 | X7: 3 | Y7: 271 | Z7: 746.88283 | AA7: 1139.4011 | AB7: 444.70645 | AC7: 216.57691 | AD7: 4 | AE7: 5 | AF7: 2.5 | AG7: =_xlfn.XLOOKUP(A7,Sheet1!A:A,Sheet1!U:U,) -> 56.15989 | AH7: =_xlfn.XLOOKUP(A7,Sheet1!A:A,Sheet1!V:V,) -> 10.211135
A8: Regenburgsgade 6, 3. tv, 8000 Aarhus C | B8: 2050470 | C8: 44221 | D8: 66 | E8: 30113.636 | F8: 3 | G8: 2 | H8: 17.6 | I8: 8 | J8: 0 | K8: 1 | L8: 1 | M8: 1 | N8: 1 | O8: 1 | P8: 76 | Q8: 0 | R8: 6 | S8: 1 | T8: 1 | U8: 2 | V8: 6 | W8: 3 | X8: 3 | Y8: 716 | Z8: 1862.047 | AA8: 1497.3617 | AB8: 1404.9896 | AC8: 1836.1869 | AD8: 5 | AE8: 8 | AF8: 7.5 | AG8: =_xlfn.XLOOKUP(A8,Sheet1!A:A,Sheet1!U:U,) -> 56.157206 | AH8: =_xlfn.XLOOKUP(A8,Sheet1!A:A,Sheet1!V:V,) -> 10.183928
A9: Sjællandsgade 5, 1, 8000 Aarhus C | B9: 2991881 | C9: 44220 | D9: 87 | E9: 33333.333 | F9: 1 | G9: 8 | H9: 5.7 | I9: 6 | J9: 1 | K9: 1 | L9: 1 | M9: 0 | N9: 1 | O9: 1 | P9: 144 | Q9: 1 | R9: 2 | S9: 1 | T9: 1 | U9: 4 | V9: 6 | W9: 3 | X9: 3 | Y9: 304 | Z9: 911.44945 | AA9: 1242.818 | AB9: 514.4751 | AC9: 369.0851 | AD9: 4 | AE9: 9 | AF9: 2.5 | AG9: =_xlfn.XLOOKUP(A9,Sheet1!A:A,Sheet1!U:U,) -> 56.161175 | AH9: =_xlfn.XLOOKUP(A9,Sheet1!A:A,Sheet1!V:V,) -> 10.209275
A10: Sønderborggade 13, 2. mf, 8000 Aarhus C | B10: 1083267 | C10: 44217 | D10: 35 | E10: 30000 | F10: 2 | G10: 1 | H10: 16.4 | I10: 3 | J10: 0 | K10: 1 | L10: 1 | M10: 0 | N10: 1 | O10: 1 | P10: 61 | Q10: 0 | R10: 3 | S10: 1 | T10: 1 | U10: 1 | V10: 6 | W10: 3 | X10: 3 | Y10: 2391 | Z10: 2398.5943 | AA10: 1779.9382 | AB10: 2353.5519 | AC10: 1843.4031 | AD10: 4 | AE10: 4 | AF10: 5 | AG10: =_xlfn.XLOOKUP(A10,Sheet1!A:A,Sheet1!U:U,) -> 56.141053 | AH10: =_xlfn.XLOOKUP(A10,Sheet1!A:A,Sheet1!V:V,) -> 10.18126
A11: Paradisgade 5, st. th, 8000 Aarhus C | B11: 1434040 | C11: 44217 | D11: 44 | E11: 31590.909 | F11: 0 | G11: 8 | H11: 3.3 | I11: 1 | J11: 0 | K11: 4 | L11: 1 | M11: 0 | N11: 1 | O11: 0 | P11: 155 | Q11: 1 | R11: 3 | S11: 1 | T11: 1 | U11: 2 | V11: 6 | W11: 6 | X11: 3 | Y11: 528 | Z11: 782.31999 | AA11: 1127.2761 | AB11: 409.06058 | AC11: 305.7877 | AD11: 3 | AE11: 5 | AF11: 0 | AG11: =_xlfn.XLOOKUP(A11,Sheet1!A:A,Sheet1!U:U,) -> 56.160038 | AH11: =_xlfn.XLOOKUP(A11,Sheet1!A:A,Sheet1!V:V,) -> 10.20971
A12: Klostergade 10, 2. th, 8000 Aarhus C | B12: 5772267 | C12: 44216 | D12: 161 | E12: 34751.553 | F12: 2 | G12: 8 | H12: 3.6 | I12: 1 | J12: 0 | K12: 4 | L12: 1 | M12: 0 | N12: 1 | O12: 1 | P12: 123 | Q12: 0 | R12: 4 | S12: 2 | T12: 1 | U12: 7 | V12: 6 | W12: 6 | X12: 3 | Y12: 1063 | Z12: 691.71437 | AA12: 1006.1633 | AB12: 287.49895 | AC12: 320.00816 | AD12: 2 | AE12: 5 | AF12: 5 | AG12: =_xlfn.XLOOKUP(A12,Sheet1!A:A,Sheet1!U:U,) -> 56.159031 | AH12: =_xlfn.XLOOKUP(A12,Sheet1!A:A,Sheet1!V:V,) -> 10.208928
A13: Vestergade 15C, 1. tv, 8000 Aarhus C | B13: 3352970 | C13: 44216 | D13: 71 | E13: 45774.648 | F13: 1 | G13: 7 | H13: 3.4 | I13: 5 | J13: 0 | K13: 1 | L13: 1 | M13: 0 | N13: 0 | O13: 1 | P13: 3 | Q13: 0 | R13: 4 | S13: 1 | T13: 1 | U13: 2 | V13: 2 | W13: 5 | X13: 3 | Y13: 749 | Z13: 683.23595 | AA13: 776.78071 | AB13: 123.57538 | AC13: 547.8823 | AD13: 7 | AE13: 3 | AF13: 2.5 | AG13: =_xlfn.XLOOKUP(A13,Sheet1!A:A,Sheet1!U:U,) -> 56.157288 | AH13: =_xlfn.XLOOKUP(A13,Sheet1!A:A,Sheet1!V:V,) -> 10.204785
... A109: Mejlgade 97, st, 8000 Aarhus C | B109: 4549723 | C109: 44164 | D109: 111 | E109: 39729.73 | F109: 0 | G109: 8 | H109: 3.8 | I109: 1 | J109: 0 | K109: 4 | L109: 1 | M109: 0 | N109: 0 | O109: 1 | P109: 125 | Q109: 1 | R109: 5 | S109: 1 | T109: 1 | U109: 4 | V109: 6 | W109: 6 | X109: 3 | Y109: 823 | Z109: 1046.636 | AA109: 1517.3026 | AB109: 839.68124 | AC109: 74.456904 | AD109: 4 | AE109: 7 | AF109: 0 | AG109: =_xlfn.XLOOKUP(A109,Sheet1!A:A,Sheet1!U:U,) -> 56.162599 | AH109: =_xlfn.XLOOKUP(A109,Sheet1!A:A,Sheet1!V:V,) -> 10.21525
A110: Telefontorvet 8, 3. 2, 8000 Aarhus C | B110: 3507723 | C110: 44164 | D110: 96 | E110: 35416.667 | F110: 3 | G110: 7 | H110: 6.2 | I110: 5 | J110: 0 | K110: 1 | L110: 3 | P110: 16 | Q110: 1 | R110: 5 | S110: 1 | T110: 1 | U110: 3 | V110: 2 | W110: 5 | X110: 3 | Y110: 7511 | Z110: 488.14817 | AA110: 626.31205 | AB110: 109.90009 | AC110: 420.23692 | AD110: 5 | AE110: 3 | AF110: 7.5 | AG110: =_xlfn.XLOOKUP(A110,Sheet1!A:A,Sheet1!U:U,) -> 56.155819 | AH110: =_xlfn.XLOOKUP(A110,Sheet1!A:A,Sheet1!V:V,) -> 10.20671
A111: Vestre Ringgade 156, 2. th, 8000 Aarhus C | B111: 2759752 | C111: 44161 | D111: 72 | E111: 37152.778 | F111: 2 | G111: 5 | H111: 46.7 | I111: 4 | J111: 1 | K111: 5 | L111: 1 | M111: 0 | N111: 1 | O111: 1 | P111: 73 | Q111: 0 | R111: 3 | S111: 1 | T111: 1 | U111: 3 | V111: 6 | W111: 3 | X111: 3 | Y111: 462 | Z111: 2067.2318 | AA111: 2018.4611 | AB111: 1502.468 | AC111: 1721.7704 | AD111: 4 | AE111: 8 | AF111: 5 | AG111: =_xlfn.XLOOKUP(A111,Sheet1!A:A,Sheet1!U:U,) -> 56.166328 | AH111: =_xlfn.XLOOKUP(A111,Sheet1!A:A,Sheet1!V:V,) -> 10.189404
A112: Klostergade 72, 1, 8000 Aarhus C | B112: 2218119 | C112: 44161 | D112: 61 | E112: 35245.902 | F112: 1 | G112: 7 | H112: 3.6 | I112: 5 | J112: 0 | K112: 4 | L112: 1 | M112: 1 | N112: 1 | O112: 1 | P112: 119 | Q112: 0 | R112: 2 | S112: 1 | T112: 1 | U112: 2 | V112: 6 | W112: 3 | X112: 3 | Y112: 124 | Z112: 856.23319 | AA112: 938.39202 | AB112: 291.61543 | AC112: 653.34766 | AD112: 5 | AE112: 3 | AF112: 2.5 | AG112: =_xlfn.XLOOKUP(A112,Sheet1!A:A,Sheet1!U:U,) -> 56.158708 | AH112: =_xlfn.XLOOKUP(A112,Sheet1!A:A,Sheet1!V:V,) -> 10.203348
A113: Silkeborgvej 138, 3. th, 8000 Aarhus C | B113: 1779653 | C113: 44160 | D113: 55 | E113: 31363.636 | F113: 3 | G113: 2 | H113: 14.1 | I113: 8 | J113: 0 | K113: 3 | L113: 1 | M113: 0 | N113: 1 | O113: 1 | P113: 82 | Q113: 0 | R113: 4 | S113: 1 | T113: 1 | U113: 2 | V113: 6 | W113: 3 | X113: 3 | Y113: 476 | Z113: 2134.4357 | AA113: 1727.6792 | AB113: 1695.5104 | AC113: 2125.425 | AD113: 4 | AE113: 8 | AF113: 7.5 | AG113: =_xlfn.XLOOKUP(A113,Sheet1!A:A,Sheet1!U:U,) -> 56.156653 | AH113: =_xlfn.XLOOKUP(A113,Sheet1!A:A,Sheet1!V:V,) -> 10.179232
A114: Grønnegade 77, 2. tv, 8000 Aarhus C | B114: 2971248 | C114: 44160 | D114: 60 | E114: 48000 | F114: 2 | G114: 7 | H114: 6.5 | I114: 5 | J114: 1 | K114: 1 | L114: 1 | M114: 0 | N114: 1 | O114: 1 | P114: 104 | Q114: 1 | R114: 5 | S114: 1 | T114: 1 | U114: 2 | V114: 6 | W114: 3 | X114: 3 | Y114: 655 | Z114: 1020.6537 | AA114: 1052.6894 | AB114: 455.97972 | AC114: 804.34095 | AD114: 4 | AE114: 9 | AF114: 5 | AG114: =_xlfn.XLOOKUP(A114,Sheet1!A:A,Sheet1!U:U,) -> 56.15956 | AH114: =_xlfn.XLOOKUP(A114,Sheet1!A:A,Sheet1!V:V,) -> 10.201138
A115: Ny Munkegade 32, 4. tv, 8000 Aarhus C | B115: 3022832 | C115: 44160 | D115: 67 | E115: 43731.343 | F115: 4 | G115: 8 | H115: 19.4 | I115: 6 | J115: 0 | K115: 1 | L115: 1 | M115: 0 | N115: 1 | O115: 1 | P115: 124 | Q115: 0 | R115: 4 | S115: 1 | T115: 1 | U115: 2 | V115: 6 | W115: 3 | X115: 3 | Y115: 842 | Z115: 1126.4247 | AA115: 1283.7755 | AB115: 592.26308 | AC115: 738.50617 | AD115: 3 | AE115: 9 | AF115: 10 | AG115: =_xlfn.XLOOKUP(A115,Sheet1!A:A,Sheet1!U:U,) -> 56.161821 | AH115: =_xlfn.XLOOKUP(A115,Sheet1!A:A,Sheet1!V:V,) -> 10.203398
A116: Rudolph Wulffs Gade 17, 3. tv, 8000 Aarhus C | B116: 2733960 | C116: 44160 | D116: 91 | E116: 29120.879 | F116: 3 | G116: 1 | H116: 14.9 | I116: 2 | J116: 0 | K116: 3 | L116: 1 | M116: 0 | N116: 1 | O116: 1 | P116: 68 | Q116: 1 | R116: 4 | S116: 1 | T116: 1 | U116: 3 | V116: 6 | W116: 3 | X116: 3 | Y116: 1448 | Z116: 2340.5133 | AA116: 1728.8989 | AB116: 2350.3185 | AC116: 1631.6332 | AD116: 3 | AE116: 6 | AF116: 7.5 | AG116: =_xlfn.XLOOKUP(A116,Sheet1!A:A,Sheet1!U:U,) -> 56.139767 | AH116: =_xlfn.XLOOKUP(A116,Sheet1!A:A,Sheet1!V:V,) -> 10.184192
A117: Klostergade 72, st, 8000 Aarhus C | B117: 2063366 | C117: 44159 | D117: 62 | E117: 32258.065 | F117: 0 | G117: 7 | H117: 3.6 | I117: 5 | J117: 0 | K117: 4 | L117: 1 | M117: 0 | N117: 1 | O117: 1 | P117: 119 | Q117: 0 | R117: 2 | S117: 1 | T117: 1 | U117: 2 | V117: 6 | W117: 3 | X117: 3 | Y117: 124 | Z117: 856.23319 | AA117: 938.39202 | AB117: 291.61543 | AC117: 653.34766 | AD117: 5 | AE117: 3 | AF117: 0 | AG117: =_xlfn.XLOOKUP(A117,Sheet1!A:A,Sheet1!U:U,) -> 56.158708 | AH117: =_xlfn.XLOOKUP(A117,Sheet1!A:A,Sheet1!V:V,) -> 10.203348
A118: Søndre Ringgade 13, st. th, 8000 Aarhus C | B118: 2476040 | C118: 44159 | D118: 64 | E118: 37500 | F118: 0 | G118: 4 | H118: 17.8 | I118: 2 | J118: 0 | K118: 4 | L118: 1 | M118: 0 | N118: 1 | O118: 1 | P118: 88 | Q118: 0 | R118: 5 | S118: 1 | T118: 1 | U118: 2 | V118: 6 | W118: 3 | X118: 3 | Y118: 726 | Z118: 1818.1231 | AA118: 1224.65 | AB118: 1902.3271 | AC118: 1207.9803 | AD118: 5 | AE118: 4 | AF118: 0 | AG118: =_xlfn.XLOOKUP(A118,Sheet1!A:A,Sheet1!U:U,) -> 56.141577 | AH118: =_xlfn.XLOOKUP(A118,Sheet1!A:A,Sheet1!V:V,) -> 10.192652
